Workbook

Sheet CLEAN DATA
A1: OrderID | B1: Date | C1: CustomerID | D1: Product | E1: Quantity | F1: Unit Price | G1: Shipping Address | H1: Payment Method | I1: Order Status | J1: Tracking Number | K1: Items In Cart | L1: Coupon Code | M1: Referral Source | N1: Total Price | O1: Year | P1: Month | Q1: Quarter | R1: OUTLIERS | S1: Time
A2: ORD200000 | B2: 44930 | C2: C72649 | D2: Monitor | E2: 5 | F2: 570.62 | G2: 928 Main St | H2: Debit Card | I2: Shipped | J2: TRK37947903 | K2: 7 | L2: SAVE10 | M2: Instagram | N2: 2853.1 | O2: 2023 | P2: January | Q2: 1 | R2: =IF(Table1_2[[#This Row],[Total Price]]>3330.41,"OUTLIER","NORMAL") -> NORMAL | S2: 0
A3: ORD200001 | B3: 45527 | C3: C75739 | D3: Phone | E3: 2 | F3: 151.35 | G3: 823 Main St | H3: Online | I3: Shipped | J3: TRK91186779 | K3: 3 | L3: SAVE10 | M3: Referral | N3: 302.7 | O3: 2024 | P3: August | Q3: 3 | R3: =IF(Table1_2[[#This Row],[Total Price]]>3330.41,"OUTLIER","NORMAL") -> NORMAL | S3: 0
A4: ORD200002 | B4: 45349 | C4: C81728 | D4: Tablet | E4: 5 | F4: 550.68 | G4: 512 Main St | H4: Credit Card | I4: Cancelled | J4: TRK42903982 | K4: 8 | L4: FREESHIP | M4: Email | N4: 2753.4 | O4: 2024 | P4: February | Q4: 1 | R4: =IF(Table1_2[[#This Row],[Total Price]]>3330.41,"OUTLIER","NORMAL") -> NORMAL | S4: 0
A5: ORD200003 | B5: 45214 | C5: C33540 | D5: Chair | E5: 1 | F5: 273.19 | G5: 275 Main St | H5: Debit Card | I5: Returned | J5: TRK62788070 | K5: 5 | L5: SAVE10 | M5: Facebook | N5: 273.19 | O5: 2023 | P5: October | Q5: 4 | R5: =IF(Table1_2[[#This Row],[Total Price]]>3330.41,"OUTLIER","NORMAL") -> NORMAL | S5: 0
A6: ORD200004 | B6: 45785 | C6: C81840 | D6: Printer | E6: 4 | F6: 626.01 | G6: 668 Main St | H6: Online | I6: Delivered | J6: TRK29241424 | K6: 8 | L6: SAVE10 | M6: Email | N6: 2504.04 | O6: 2025 | P6: May | Q6: 2 | R6: =IF(Table1_2[[#This Row],[Total Price]]>3330.41,"OUTLIER","NORMAL") -> NORMAL | S6: 0
A7: ORD200005 | B7: 45222 | C7: C37249 | D7: Phone | E7: 2 | F7: 245.86 | G7: 934 Main St | H7: Credit Card | I7: Shipped | J7: TRK72976927 | K7: 4 | L7: SAVE10 | M7: Instagram | N7: 491.72 | O7: 2023 | P7: October | Q7: 4 | R7: =IF(Table1_2[[#This Row],[Total Price]]>3330.41,"OUTLIER","NORMAL") -> NORMAL | S7: 0
A8: ORD200006 | B8: 45825 | C8: C83492 | D8: Laptop | E8: 1 | F8: 664.42 | G8: 986 Main St | H8: Gift Card | I8: Returned | J8: TRK96417362 | K8: 6 | L8: SAVE10 | M8: Facebook | N8: 664.42 | O8: 2025 | P8: June | Q8: 2 | R8: =IF(Table1_2[[#This Row],[Total Price]]>3330.41,"OUTLIER","NORMAL") -> NORMAL | S8: 0
A9: ORD200007 | B9: 45058 | C9: C41460 | D9: Monitor | E9: 5 | F9: 149.55 | G9: 706 Main St | H9: Cash | I9: Shipped | J9: TRK78809193 | K9: 9 | L9: FREESHIP | M9: Facebook | N9: 747.75 | O9: 2023 | P9: May | Q9: 2 | R9: =IF(Table1_2[[#This Row],[Total Price]]>3330.41,"OUTLIER","NORMAL") -> NORMAL | S9: 0
A10: ORD200008 | B10: 45749 | C10: C26817 | D10: Phone | E10: 2 | F10: 134.28 | G10: 904 Main St | H10: Gift Card | I10: Cancelled | J10: TRK61042692 | K10: 2 | L10: NO COUPON | M10: Email | N10: 268.56 | O10: 2025 | P10: April | Q10: 2 | R10: =IF(Table1_2[[#This Row],[Total Price]]>3330.41,"OUTLIER","NORMAL") -> NORMAL | S10: 0
A11: ORD200009 | B11: 45251 | C11: C31946 | D11: Desk | E11: 4 | F11: 509.38 | G11: 102 Main St | H11: Credit Card | I11: Shipped | J11: TRK33478363 | K11: 6 | L11: SAVE10 | M11: Google | N11: 2037.52 | O11: 2023 | P11: November | Q11: 4 | R11: =IF(Table1_2[[#This Row],[Total Price]]>3330.41,"OUTLIER","NORMAL") -> NORMAL | S11: 0
A12: ORD200010 | B12: 45289 | C12: C43443 | D12: Tablet | E12: 5 | F12: 625.97 | G12: 333 Main St | H12: Credit Card | I12: Returned | J12: TRK98859248 | K12: 9 | L12: WINTER15 | M12: Instagram | N12: 3129.85 | O12: 2023 | P12: December | Q12: 4 | R12: =IF(Table1_2[[#This Row],[Total Price]]>3330.41,"OUTLIER","NORMAL") -> NORMAL | S12: 0
A13: ORD200011 | B13: 45339 | C13: C93861 | D13: Monitor | E13: 3 | F13: 49.14 | G13: 831 Main St | H13: Online | I13: Returned | J13: TRK48234646 | K13: 7 | L13: SAVE10 | M13: Email | N13: 147.42 | O13: 2024 | P13: February | Q13: 1 | R13: =IF(Table1_2[[#This Row],[Total Price]]>3330.41,"OUTLIER","NORMAL") -> NORMAL | S13: 0
... A1201: ORD201199 | B1201: 45088 | C1201: C57502 | D1201: Tablet | E1201: 4 | F1201: 560.58 | G1201: 201 Main St | H1201: Gift Card | I1201: Returned | J1201: TRK51116746 | K1201: 6 | L1201: SAVE10 | M1201: Referral | N1201: 2242.32 | O1201: 2023 | P1201: June | Q1201: 2 | R1201: =IF(Table1_2[[#This Row],[Total Price]]>3330.41,"OUTLIER","NORMAL") -> NORMAL | S1201: 0

Sheet STATISTICAL TABLE
A1: COLUMN | B1: COUNT | C1: MEAN | D1: MEDIAN | F1: TRENDS BY YEAR | G1: TOTAL ORDER
A2: QUANTITY | B2: =COUNT('CLEAN DATA'!E:E) -> 1200 | C2: =AVERAGE('CLEAN DATA'!E:E) -> 2.9458333 | D2: =MEDIAN('CLEAN DATA'!E:E) -> 3 | F2: 2023 | G2: =COUNTIF('CLEAN DATA'!O:O,Table1_2[[#This Row],[Year]]) -> 510
A3: UNIT PRICE | B3: =COUNT('CLEAN DATA'!F:F) -> 1200 | C3: =AVERAGE('CLEAN DATA'!F:F) -> 356.41275 | D3: =MEDIAN('CLEAN DATA'!F:F) -> 364.21 | F3: 2024 | G3: =COUNTIF('CLEAN DATA'!O:O,Table1_2[[#This Row],[Year]]) -> 459
A4: TOTAL PRICE | B4: =COUNT('CLEAN DATA'!N:N) -> 1200 | C4: =AVERAGE('CLEAN DATA'!N:N) -> 1053.9683 | D4: =MEDIAN('CLEAN DATA'!N:N) -> 823.615 | F4: 2025 | G4: =COUNTIF('CLEAN DATA'!O:O,'CLEAN DATA'!O6) -> 231
A5: ITEMS IN CART | B5: =COUNT('CLEAN DATA'!K:K) -> 1200 | C5: =AVERAGE('CLEAN DATA'!K:K) -> 5.485 | D5: =MEDIAN('CLEAN DATA'!K:K) -> 5
A6: YEAR | B6: =COUNT('CLEAN DATA'!O:O) -> 1200 | C6: =AVERAGE('CLEAN DATA'!O:O) -> 2023.7675 | D6: =MEDIAN('CLEAN DATA'!O:O) -> 2024
A7: QUARTER | B7: =COUNT('CLEAN DATA'!Q:Q) -> 1200 | C7: =COUNT('CLEAN DATA'!Q:Q) -> 1200 | D7: =MEDIAN('CLEAN DATA'!Q:Q) -> 2
H9: REVENUE TREND
A10: PRODUCTS | B10: REVENUE | H10: Average Total Price | I10: =AVERAGE('CLEAN DATA'!N:N) -> 1053.9683
A11: Chairs | B11: =SUMIFS('CLEAN DATA'!N:N,'CLEAN DATA'!D:D,'CLEAN DATA'!D5) -> 195620.11 | H11: Median Total Price | I11: =MEDIAN('CLEAN DATA'!N:N) -> 823.615
A12: Printer | B12: =SUMIFS('CLEAN DATA'!N:N,'CLEAN DATA'!D:D,'CLEAN DATA'!D6) -> 195612.61
A13: Laptop | B13: =SUMIFS('CLEAN DATA'!N:N,'CLEAN DATA'!D:D,'CLEAN DATA'!D8) -> 192126.56
A14: Tablets | B14: =SUMIFS('CLEAN DATA'!N:N,'CLEAN DATA'!D:D,'CLEAN DATA'!D16) -> 186568.95
A15: Monitor | B15: =SUMIFS('CLEAN DATA'!N:N,'CLEAN DATA'!D:D,'CLEAN DATA'!D2) -> 175651.41
A16: Desk | B16: =SUMIFS('CLEAN DATA'!N:N,'CLEAN DATA'!D:D,'CLEAN DATA'!D11) -> 167459.93
A17: Phone | B17: =SUMIFS('CLEAN DATA'!N:N,'CLEAN DATA'!D:D,'CLEAN DATA'!D7) -> 151722.39

Sheet OUTLIERS
A1: OUTLIERS
A2: =_xlfn.QUARTILE.INC('CLEAN DATA'!N:N,1) -> 410.52 | E2: =A2-1.5*B5 -> -1341.4125
A3: =_xlfn.QUARTILE.INC('CLEAN DATA'!N:N,3) -> 1578.475 | E3: =A3+1.5*B5 -> 3330.4075
A5: IQR | B5: =A3-A2 -> 1167.955
B6: COLUMN | C6: OUTLIERS
B7: QUANTITY | C7: NO
B8: UNIT PRICE | C8: NO
B9: TOTAL PRICE | C9: 8
B10: ITEMS IN CART | C10: NO
B12: OUTLIERS IN TOTAL PRICE ARE 109, 328, 330, 471, 634, 791, 1067, 1124
A13: OrderID | B13: Date | C13: CustomerID | D13: Product | E13: Quantity | F13: Unit Price | G13: Shipping Address | H13: Payment Method | I13: Order Status | J13: Tracking Number | K13: Items In Cart | L13: Coupon Code | M13: Referral Source | N13: Total Price | O13: Year | P13: Month | Q13: Quarter | R13: OUTLIERS
A14: ORD200107 | B14: 45012 | C14: C16775 | D14: Printer | E14: 5 | F14: 670.75 | G14: 848 Main St | H14: Gift Card | I14: Shipped | J14: TRK34392124 | K14: 8 | L14: FREESHIP | M14: Instagram | N14: 3353.75 | O14: 2023 | P14: March | Q14: 1 | R14: OUTLIER
A15: ORD200326 | B15: 45474 | C15: C65986 | D15: Laptop | E15: 5 | F15: 670.48 | G15: 273 Main St | H15: Gift Card | I15: Returned | J15: TRK98353867 | K15: 5 | L15: SAVE10 | M15: Facebook | N15: 3352.4 | O15: 2024 | P15: July | Q15: 3 | R15: OUTLIER
A16: ORD200328 | B16: 44985 | C16: C18404 | D16: Tablet | E16: 5 | F16: 674.04 | G16: 546 Main St | H16: Online | I16: Cancelled | J16: TRK89401624 | K16: 7 | L16: SAVE10 | M16: Google | N16: 3370.2 | O16: 2023 | P16: February | Q16: 1 | R16: OUTLIER
A17: ORD200469 | B17: 45256 | C17: C13877 | D17: Chair | E17: 5 | F17: 676.98 | G17: 893 Main St | H17: Cash | I17: Cancelled | J17: TRK17254691 | K17: 5 | L17: NO COUPON | M17: Facebook | N17: 3384.9 | O17: 2023 | P17: November | Q17: 4 | R17: OUTLIER
A18: ORD200632 | B18: 45048 | C18: C67260 | D18: Laptop | E18: 5 | F18: 678.16 | G18: 463 Main St | H18: Gift Card | I18: Delivered | J18: TRK38229104 | K18: 7 | L18: WINTER15 | M18: Facebook | N18: 3390.8 | O18: 2023 | P18: May | Q18: 2 | R18: OUTLIER
A19: ORD200789 | B19: 45155 | C19: C57276 | D19: Tablet | E19: 5 | F19: 691.28 | G19: 183 Main St | H19: Online | I19: Delivered | J19: TRK75899752 | K19: 10 | L19: SAVE10 | M19: Email | N19: 3456.4 | O19: 2023 | P19: August | Q19: 3 | R19: OUTLIER
A20: ORD201065 | B20: 45229 | C20: C47778 | D20: Printer | E20: 5 | F20: 666.8 | G20: 488 Main St | H20: Debit Card | I20: Delivered | J20: TRK79504329 | K20: 7 | L20: SAVE10 | M20: Referral | N20: 3334 | O20: 2023 | P20: October | Q20: 4 | R20: OUTLIER
A21: ORD201122 | B21: 45084 | C21: C38840 | D21: Monitor | E21: 5 | F21: 678.19 | G21: 766 Main St | H21: Online | I21: Returned | J21: TRK32496970 | K21: 8 | L21: NO COUPON | M21: Facebook | N21: 3390.95 | O21: 2023 | P21: June | Q21: 2 | R21: OUTLIER

Sheet KEY OBSERVATIONS

Sheet MESSY DATA
A1: OrderID | B1: Date | C1: CustomerID | D1: Product | E1: Quantity | F1: UnitPrice | G1: ShippingAddress | H1: PaymentMethod | I1: OrderStatus | J1: TrackingNumber | K1: ItemsInCart | L1: CouponCode | M1: ReferralSource | N1: TotalPrice
A2: ORD200000 | B2: 44930 | C2: C72649 | D2: Monitor | E2: 5 | F2: 570.62 | G2: 928 Main St | H2: Debit Card | I2: Shipped | J2: TRK37947903 | K2: 7 | L2: SAVE10 | M2: Instagram | N2: 2853.1
A3: ORD200001 | B3: 45527 | C3: C75739 | D3: Phone | E3: 2 | F3: 151.35 | G3: 823 Main St | H3: Online | I3: Shipped | J3: TRK91186779 | K3: 3 | L3: SAVE10 | M3: Referral | N3: 302.7
A4: ORD200002 | B4: 45349 | C4: C81728 | D4: Tablet | E4: 5 | F4: 550.68 | G4: 512 Main St | H4: Credit Card | I4: Cancelled | J4: TRK42903982 | K4: 8 | L4: FREESHIP | M4: Email | N4: 2753.4
A5: ORD200003 | B5: 45214 | C5: C33540 | D5: Chair | E5: 1 | F5: 273.19 | G5: 275 Main St | H5: Debit Card | I5: Returned | J5: TRK62788070 | K5: 5 | L5: SAVE10 | M5: Facebook | N5: 273.19
A6: ORD200004 | B6: 45785 | C6: C81840 | D6: Printer | E6: 4 | F6: 626.01 | G6: 668 Main St | H6: Online | I6: Delivered | J6: TRK29241424 | K6: 8 | L6: SAVE10 | M6: Email | N6: 2504.04
A7: ORD200005 | B7: 45222 | C7: C37249 | D7: Phone | E7: 2 | F7: 245.86 | G7: 934 Main St | H7: Credit Card | I7: Shipped | J7: TRK72976927 | K7: 4 | L7: SAVE10 | M7: Instagram | N7: 491.72
A8: ORD200006 | B8: 45825 | C8: C83492 | D8: Laptop | E8: 1 | F8: 664.42 | G8: 986 Main St | H8: Gift Card | I8: Returned | J8: TRK96417362 | K8: 6 | L8: SAVE10 | M8: Facebook | N8: 664.42
A9: ORD200007 | B9: 45058 | C9: C41460 | D9: Monitor | E9: 5 | F9: 149.55 | G9: 706 Main St | H9: Cash | I9: Shipped | J9: TRK78809193 | K9: 9 | L9: FREESHIP | M9: Facebook | N9: 747.75
A10: ORD200008 | B10: 45749 | C10: C26817 | D10: Phone | E10: 2 | F10: 134.28 | G10: 904 Main St | H10: Gift Card | I10: Cancelled | J10: TRK61042692 | K10: 2 | M10: Email | N10: 268.56
A11: ORD200009 | B11: 45251 | C11: C31946 | D11: Desk | E11: 4 | F11: 509.38 | G11: 102 Main St | H11: Credit Card | I11: Shipped | J11: TRK33478363 | K11: 6 | L11: SAVE10 | M11: Google | N11: 2037.52
A12: ORD200010 | B12: 45289 | C12: C43443 | D12: Tablet | E12: 5 | F12: 625.97 | G12: 333 Main St | H12: Credit Card | I12: Returned | J12: TRK98859248 | K12: 9 | L12: WINTER15 | M12: Instagram | N12: 3129.85
A13: ORD200011 | B13: 45339 | C13: C93861 | D13: Monitor | E13: 3 | F13: 49.14 | G13: 831 Main St | H13: Online | I13: Returned | J13: TRK48234646 | K13: 7 | L13: SAVE10 | M13: Email | N13: 147.42
A14: ORD200012 | B14: 45580 | C14: C38785 | D14: Monitor | E14: 2 | F14: 180.5 | G14: 179 Main St | H14: Debit Card | I14: Pending | J14: TRK20419991 | K14: 6 | L14: FREESHIP | M14: Referral | N14: 361
A15: ORD200013 | B15: 45168 | C15: C88348 | D15: Laptop | E15: 3 | F15: 201.49 | G15: 903 Main St | H15: Credit Card | I15: Returned | J15: TRK81913874 | K15: 4 | L15: FREESHIP | M15: Facebook | N15: 604.47
A16: ORD200014 | B16: 45012 | C16: C98474 | D16: Tablet | E16: 2 | F16: 393.33 | G16: 980 Main St | H16: Debit Card | I16: Pending | J16: TRK79186539 | K16: 3 | L16: SAVE10 | M16: Instagram | N16: 786.66
A17: ORD200015 | B17: 45124 | C17: C39416 | D17: Printer | E17: 1 | F17: 473.96 | G17: 942 Main St | H17: Cash | I17: Delivered | J17: TRK54930938 | K17: 3 | M17: Google | N17: 473.96
A18: ORD200016 | B18: 44950 | C18: C28976 | D18: Printer | E18: 2 | F18: 533.81 | G18: 914 Main St | H18: Credit Card | I18: Pending | J18: TRK13194259 | K18: 3 | L18: FREESHIP | M18: Email | N18: 1067.62
A19: ORD200017 | B19: 45353 | C19: C60672 | D19: Tablet | E19: 1 | F19: 423.4 | G19: 382 Main St | H19: Debit Card | I19: Shipped | J19: TRK11972116 | K19: 3 | M19: Referral | N19: 423.4
A20: ORD200018 | B20: 45742 | C20: C84329 | D20: Desk | E20: 1 | F20: 431.44 | G20: 891 Main St | H20: Gift Card | I20: Pending | J20: TRK65191045 | K20: 3 | L20: SAVE10 | M20: Facebook | N20: 431.44
A21: ORD200019 | B21: 44949 | C21: C14552 | D21: Monitor | E21: 5 | F21: 224 | G21: 273 Main St | H21: Cash | I21: Returned | J21: TRK59101365 | K21: 9 | L21: SAVE10 | M21: Google | N21: 1120
A22: ORD200020 | B22: 45054 | C22: C54829 | D22: Chair | E22: 5 | F22: 62.51 | G22: 587 Main St | H22: Cash | I22: Pending | J22: TRK16718651 | K22: 9 | L22: WINTER15 | M22: Instagram | N22: 312.55
A23: ORD200021 | B23: 45613 | C23: C99023 | D23: Monitor | E23: 4 | F23: 342.95 | G23: 569 Main St | H23: Cash | I23: Delivered | J23: TRK52646983 | K23: 6 | M23: Google | N23: 1371.8
A24: ORD200022 | B24: 44955 | C24: C34416 | D24: Monitor | E24: 2 | F24: 49.62 | G24: 633 Main St | H24: Online | I24: Pending | J24: TRK75937350 | K24: 2 | L24: SAVE10 | M24: Google | N24: 99.24
A25: ORD200023 | B25: 45756 | C25: C42372 | D25: Phone | E25: 4 | F25: 273.25 | G25: 755 Main St | H25: Debit Card | I25: Cancelled | J25: TRK36168083 | K25: 5 | L25: FREESHIP | M25: Referral | N25: 1093
A26: ORD200024 | B26: 45595 | C26: C17470 | D26: Laptop | E26: 2 | F26: 230.95 | G26: 956 Main St | H26: Online | I26: Delivered | J26: TRK28775057 | K26: 3 | L26: WINTER15 | M26: Referral | N26: 461.9
A27: ORD200025 | B27: 45497 | C27: C42577 | D27: Monitor | E27: 1 | F27: 399.98 | G27: 709 Main St | H27: Debit Card | I27: Delivered | J27: TRK69423327 | K27: 3 | L27: WINTER15 | M27: Email | N27: 399.98
A28: ORD200026 | B28: 45357 | C28: C21944 | D28: Laptop | E28: 5 | F28: 59.55 | G28: 296 Main St | H28: Online | I28: Delivered | J28: TRK80276812 | K28: 6 | M28: Referral | N28: 297.75
A29: ORD200027 | B29: 45344 | C29: C97593 | D29: Printer | E29: 1 | F29: 472.74 | G29: 881 Main St | H29: Online | I29: Shipped | J29: TRK89117573 | K29: 6 | L29: WINTER15 | M29: Google | N29: 472.74
A30: ORD200028 | B30: 45251 | C30: C59823 | D30: Phone | E30: 4 | F30: 160.07 | G30: 568 Main St | H30: Online | I30: Pending | J30: TRK65895539 | K30: 5 | M30: Email | N30: 640.28
A31: ORD200029 | B31: 45555 | C31: C33260 | D31: Desk | E31: 3 | F31: 423.53 | G31: 930 Main St | H31: Credit Card | I31: Delivered | J31: TRK59744090 | K31: 6 | L31: SAVE10 | M31: Referral | N31: 1270.59
A32: ORD200030 | B32: 45738 | C32: C44267 | D32: Monitor | E32: 2 | F32: 426.7 | G32: 895 Main St | H32: Online | I32: Pending | J32: TRK54751444 | K32: 5 | L32: SAVE10 | M32: Referral | N32: 853.4
A33: ORD200031 | B33: 45107 | C33: C26445 | D33: Chair | E33: 3 | F33: 500.08 | G33: 996 Main St | H33: Debit Card | I33: Returned | J33: TRK31229981 | K33: 6 | M33: Facebook | N33: 1500.24
A34: ORD200032 | B34: 45047 | C34: C12388 | D34: Tablet | E34: 5 | F34: 536.72 | G34: 830 Main St | H34: Cash | I34: Delivered | J34: TRK99261395 | K34: 10 | M34: Email | N34: 2683.6
A35: ORD200033 | B35: 45082 | C35: C52184 | D35: Chair | E35: 1 | F35: 162.77 | G35: 912 Main St | H35: Online | I35: Cancelled | J35: TRK73312471 | K35: 4 | L35: WINTER15 | M35: Facebook | N35: 162.77
A36: ORD200034 | B36: 44933 | C36: C67195 | D36: Chair | E36: 4 | F36: 576.52 | G36: 926 Main St | H36: Credit Card | I36: Pending | J36: TRK55467915 | K36: 5 | L36: WINTER15 | M36: Facebook | N36: 2306.08
A37: ORD200035 | B37: 45633 | C37: C50304 | D37: Monitor | E37: 2 | F37: 465.15 | G37: 128 Main St | H37: Online | I37: Shipped | J37: TRK46850888 | K37: 2 | L37: SAVE10 | M37: Facebook | N37: 930.3
A38: ORD200036 | B38: 45785 | C38: C59337 | D38: Laptop | E38: 2 | F38: 534.43 | G38: 465 Main St | H38: Debit Card | I38: Pending | J38: TRK50961250 | K38: 5 | M38: Facebook | N38: 1068.86
A39: ORD200037 | B39: 45579 | C39: C10054 | D39: Laptop | E39: 2 | F39: 76.74 | G39: 409 Main St | H39: Cash | I39: Returned | J39: TRK94005261 | K39: 7 | L39: SAVE10 | M39: Instagram | N39: 153.48
A40: ORD200038 | B40: 45645 | C40: C15924 | D40: Laptop | E40: 1 | F40: 245.89 | G40: 549 Main St | H40: Debit Card | I40: Delivered | J40: TRK14835975 | K40: 3 | L40: SAVE10 | M40: Google | N40: 245.89
...
